Workbook

Sheet Trade Log
A1: Date | B1: Time | C1: Ticker | D1: Side | E1: Strategy | F1: Entry Price | G1: Exit Price | H1: Position Size | I1: Gross P&L | J1: Fees | K1: Net P&L | L1: R-Multiple | M1: Notes | N1: Screenshot Link
A2: 46082 | B2: 0.39930556 | C2: AAPL | D2: Long | E2: Breakout | F2: 178.5 | G2: 181.2 | H2: 100 | I2: =IF(D2="Long",(G2-F2)*H2,(F2-G2)*H2) | J2: 2 | K2: =I2-J2 | L2: =IFERROR(K2/ABS(AVERAGEIF(K2:K101,"<"&0)),"") | M2: Clean breakout above resistance
A3: 46082 | B3: 0.42708333 | C3: TSLA | D3: Short | E3: Mean Reversion | F3: 245 | G3: 248.5 | H3: 50 | I3: =IF(D3="Long",(G3-F3)*H3,(F3-G3)*H3) | J3: 1.5 | K3: =I3-J3 | L3: =IFERROR(K3/ABS(AVERAGEIF(K2:K101,"<"&0)),"") | M3: Stopped out - trend too strong
A4: 46082 | B4: 0.57291667 | C4: NVDA | D4: Long | E4: Momentum | F4: 890 | G4: 897.5 | H4: 30 | I4: =IF(D4="Long",(G4-F4)*H4,(F4-G4)*H4) | J4: 2.5 | K4: =I4-J4 | L4: =IFERROR(K4/ABS(AVERAGEIF(K2:K101,"<"&0)),"") | M4: Held through pullback
A5: 46083 | B5: 0.39722222 | C5: SPY | D5: Long | E5: Gap & Go | F5: 512.3 | G5: 514.8 | H5: 200 | I5: =IF(D5="Long",(G5-F5)*H5,(F5-G5)*H5) | J5: 3 | K5: =I5-J5 | L5: =IFERROR(K5/ABS(AVERAGEIF(K2:K101,"<"&0)),"") | M5: Strong gap up follow-through
A6: 46083 | B6: 0.47222222 | C6: META | D6: Short | E6: Rejection | F6: 520 | G6: 515.5 | H6: 40 | I6: =IF(D6="Long",(G6-F6)*H6,(F6-G6)*H6) | J6: 1.8 | K6: =I6-J6 | L6: =IFERROR(K6/ABS(AVERAGEIF(K2:K101,"<"&0)),"") | M6: Clean rejection at daily level
I7: =IF(D7="Long",(G7-F7)*H7,(F7-G7)*H7) | K7: =I7-J7 | L7: =IFERROR(K7/ABS(AVERAGEIF(K2:K101,"<"&0)),"")
I8: =IF(D8="Long",(G8-F8)*H8,(F8-G8)*H8) | K8: =I8-J8 | L8: =IFERROR(K8/ABS(AVERAGEIF(K2:K101,"<"&0)),"")
I9: =IF(D9="Long",(G9-F9)*H9,(F9-G9)*H9) | K9: =I9-J9 | L9: =IFERROR(K9/ABS(AVERAGEIF(K2:K101,"<"&0)),"")
I10: =IF(D10="Long",(G10-F10)*H10,(F10-G10)*H10) | K10: =I10-J10 | L10: =IFERROR(K10/ABS(AVERAGEIF(K2:K101,"<"&0)),"")
I11: =IF(D11="Long",(G11-F11)*H11,(F11-G11)*H11) | K11: =I11-J11 | L11: =IFERROR(K11/ABS(AVERAGEIF(K2:K101,"<"&0)),"")
I12: =IF(D12="Long",(G12-F12)*H12,(F12-G12)*H12) | K12: =I12-J12 | L12: =IFERROR(K12/ABS(AVERAGEIF(K2:K101,"<"&0)),"")
I13: =IF(D13="Long",(G13-F13)*H13,(F13-G13)*H13) | K13: =I13-J13 | L13: =IFERROR(K13/ABS(AVERAGEIF(K2:K101,"<"&0)),"")
I14: =IF(D14="Long",(G14-F14)*H14,(F14-G14)*H14) | K14: =I14-J14 | L14: =IFERROR(K14/ABS(AVERAGEIF(K2:K101,"<"&0)),"")
I15: =IF(D15="Long",(G15-F15)*H15,(F15-G15)*H15) | K15: =I15-J15 | L15: =IFERROR(K15/ABS(AVERAGEIF(K2:K101,"<"&0)),"")
I16: =IF(D16="Long",(G16-F16)*H16,(F16-G16)*H16) | K16: =I16-J16 | L16: =IFERROR(K16/ABS(AVERAGEIF(K2:K101,"<"&0)),"")
I17: =IF(D17="Long",(G17-F17)*H17,(F17-G17)*H17) | K17: =I17-J17 | L17: =IFERROR(K17/ABS(AVERAGEIF(K2:K101,"<"&0)),"")
I18: =IF(D18="Long",(G18-F18)*H18,(F18-G18)*H18) | K18: =I18-J18 | L18: =IFERROR(K18/ABS(AVERAGEIF(K2:K101,"<"&0)),"")
I19: =IF(D19="Long",(G19-F19)*H19,(F19-G19)*H19) | K19: =I19-J19 | L19: =IFERROR(K19/ABS(AVERAGEIF(K2:K101,"<"&0)),"")
I20: =IF(D20="Long",(G20-F20)*H20,(F20-G20)*H20) | K20: =I20-J20 | L20: =IFERROR(K20/ABS(AVERAGEIF(K2:K101,"<"&0)),"")
I21: =IF(D21="Long",(G21-F21)*H21,(F21-G21)*H21) | K21: =I21-J21 | L21: =IFERROR(K21/ABS(AVERAGEIF(K2:K101,"<"&0)),"")
I22: =IF(D22="Long",(G22-F22)*H22,(F22-G22)*H22) | K22: =I22-J22 | L22: =IFERROR(K22/ABS(AVERAGEIF(K2:K101,"<"&0)),"")
I23: =IF(D23="Long",(G23-F23)*H23,(F23-G23)*H23) | K23: =I23-J23 | L23: =IFERROR(K23/ABS(AVERAGEIF(K2:K101,"<"&0)),"")
I24: =IF(D24="Long",(G24-F24)*H24,(F24-G24)*H24) | K24: =I24-J24 | L24: =IFERROR(K24/ABS(AVERAGEIF(K2:K101,"<"&0)),"")
I25: =IF(D25="Long",(G25-F25)*H25,(F25-G25)*H25) | K25: =I25-J25 | L25: =IFERROR(K25/ABS(AVERAGEIF(K2:K101,"<"&0)),"")
I26: =IF(D26="Long",(G26-F26)*H26,(F26-G26)*H26) | K26: =I26-J26 | L26: =IFERROR(K26/ABS(AVERAGEIF(K2:K101,"<"&0)),"")
I27: =IF(D27="Long",(G27-F27)*H27,(F27-G27)*H27) | K27: =I27-J27 | L27: =IFERROR(K27/ABS(AVERAGEIF(K2:K101,"<"&0)),"")
I28: =IF(D28="Long",(G28-F28)*H28,(F28-G28)*H28) | K28: =I28-J28 | L28: =IFERROR(K28/ABS(AVERAGEIF(K2:K101,"<"&0)),"")
I29: =IF(D29="Long",(G29-F29)*H29,(F29-G29)*H29) | K29: =I29-J29 | L29: =IFERROR(K29/ABS(AVERAGEIF(K2:K101,"<"&0)),"")
I30: =IF(D30="Long",(G30-F30)*H30,(F30-G30)*H30) | K30: =I30-J30 | L30: =IFERROR(K30/ABS(AVERAGEIF(K2:K101,"<"&0)),"")
I31: =IF(D31="Long",(G31-F31)*H31,(F31-G31)*H31) | K31: =I31-J31 | L31: =IFERROR(K31/ABS(AVERAGEIF(K2:K101,"<"&0)),"")
I32: =IF(D32="Long",(G32-F32)*H32,(F32-G32)*H32) | K32: =I32-J32 | L32: =IFERROR(K32/ABS(AVERAGEIF(K2:K101,"<"&0)),"")
I33: =IF(D33="Long",(G33-F33)*H33,(F33-G33)*H33) | K33: =I33-J33 | L33: =IFERROR(K33/ABS(AVERAGEIF(K2:K101,"<"&0)),"")
I34: =IF(D34="Long",(G34-F34)*H34,(F34-G34)*H34) | K34: =I34-J34 | L34: =IFERROR(K34/ABS(AVERAGEIF(K2:K101,"<"&0)),"")
I35: =IF(D35="Long",(G35-F35)*H35,(F35-G35)*H35) | K35: =I35-J35 | L35: =IFERROR(K35/ABS(AVERAGEIF(K2:K101,"<"&0)),"")
I36: =IF(D36="Long",(G36-F36)*H36,(F36-G36)*H36) | K36: =I36-J36 | L36: =IFERROR(K36/ABS(AVERAGEIF(K2:K101,"<"&0)),"")
I37: =IF(D37="Long",(G37-F37)*H37,(F37-G37)*H37) | K37: =I37-J37 | L37: =IFERROR(K37/ABS(AVERAGEIF(K2:K101,"<"&0)),"")
I38: =IF(D38="Long",(G38-F38)*H38,(F38-G38)*H38) | K38: =I38-J38 | L38: =IFERROR(K38/ABS(AVERAGEIF(K2:K101,"<"&0)),"")
I39: =IF(D39="Long",(G39-F39)*H39,(F39-G39)*H39) | K39: =I39-J39 | L39: =IFERROR(K39/ABS(AVERAGEIF(K2:K101,"<"&0)),"")
I40: =IF(D40="Long",(G40-F40)*H40,(F40-G40)*H40) | K40: =I40-J40 | L40: =IFERROR(K40/ABS(AVERAGEIF(K2:K101,"<"&0)),"")
...

Sheet Dashboard
A1: Trading Dashboard
A2: Auto-calculated from your Trade Log
A4: Total Trades | C4: Win Rate | E4: Total Net P&L | G4: Avg Win | I4: Avg Loss | K4: Profit Factor | M4: Largest Win | O4: Largest Loss
A5: =COUNTA('Trade Log'!A2:A101) | C5: =IFERROR(COUNTIF('Trade Log'!K2:K101,">"&0)/COUNTA('Trade Log'!K2:K101),0) | E5: =SUM('Trade Log'!K2:K101) | G5: =IFERROR(AVERAGEIF('Trade Log'!K2:K101,">"&0),0) | I5: =IFERROR(AVERAGEIF('Trade Log'!K2:K101,"<"&0),0) | K5: =IFERROR(SUMIF('Trade Log'!K2:K101,">"&0)/ABS(SUMIF('Trade Log'!K2:K101,"<"&0)),0) | M5: =IFERROR(MAX('Trade Log'!K2:K101),0) | O5: =IFERROR(MIN('Trade Log'!K2:K101),0)
A8: Cumulative P&L | E8: Strategy Breakdown
A9: Trade # | B9: Net P&L | C9: Cumulative P&L | E9: Strategy | F9: Trades | G9: Wins | H9: Win Rate | I9: Total P&L | J9: Avg P&L
A10: =IF('Trade Log'!A2="","",1) | B10: =IF('Trade Log'!K2="","",'Trade Log'!K2) | C10: =IF(B10="","",B10) | E10: Breakout | F10: =COUNTIF('Trade Log'!E2:E101,E10) | G10: =COUNTIFS('Trade Log'!E2:E101,E10,'Trade Log'!K2:K101,">"&0) | H10: =IFERROR(G10/F10,0) | I10: =SUMIF('Trade Log'!E2:E101,E10,'Trade Log'!K2:K101) | J10: =IFERROR(I10/F10,0)
A11: =IF('Trade Log'!A3="","",2) | B11: =IF('Trade Log'!K3="","",'Trade Log'!K3) | C11: =IF(B11="","",C10+B11) | E11: Mean Reversion | F11: =COUNTIF('Trade Log'!E2:E101,E11) | G11: =COUNTIFS('Trade Log'!E2:E101,E11,'Trade Log'!K2:K101,">"&0) | H11: =IFERROR(G11/F11,0) | I11: =SUMIF('Trade Log'!E2:E101,E11,'Trade Log'!K2:K101) | J11: =IFERROR(I11/F11,0)
A12: =IF('Trade Log'!A4="","",3) | B12: =IF('Trade Log'!K4="","",'Trade Log'!K4) | C12: =IF(B12="","",C11+B12) | E12: Momentum | F12: =COUNTIF('Trade Log'!E2:E101,E12) | G12: =COUNTIFS('Trade Log'!E2:E101,E12,'Trade Log'!K2:K101,">"&0) | H12: =IFERROR(G12/F12,0) | I12: =SUMIF('Trade Log'!E2:E101,E12,'Trade Log'!K2:K101) | J12: =IFERROR(I12/F12,0)
A13: =IF('Trade Log'!A5="","",4) | B13: =IF('Trade Log'!K5="","",'Trade Log'!K5) | C13: =IF(B13="","",C12+B13) | E13: Gap & Go | F13: =COUNTIF('Trade Log'!E2:E101,E13) | G13: =COUNTIFS('Trade Log'!E2:E101,E13,'Trade Log'!K2:K101,">"&0) | H13: =IFERROR(G13/F13,0) | I13: =SUMIF('Trade Log'!E2:E101,E13,'Trade Log'!K2:K101) | J13: =IFERROR(I13/F13,0)
A14: =IF('Trade Log'!A6="","",5) | B14: =IF('Trade Log'!K6="","",'Trade Log'!K6) | C14: =IF(B14="","",C13+B14) | E14: Rejection | F14: =COUNTIF('Trade Log'!E2:E101,E14) | G14: =COUNTIFS('Trade Log'!E2:E101,E14,'Trade Log'!K2:K101,">"&0) | H14: =IFERROR(G14/F14,0) | I14: =SUMIF('Trade Log'!E2:E101,E14,'Trade Log'!K2:K101) | J14: =IFERROR(I14/F14,0)
A15: =IF('Trade Log'!A7="","",6) | B15: =IF('Trade Log'!K7="","",'Trade Log'!K7) | C15: =IF(B15="","",C14+B15) | E15: Scalp | F15: =COUNTIF('Trade Log'!E2:E101,E15) | G15: =COUNTIFS('Trade Log'!E2:E101,E15,'Trade Log'!K2:K101,">"&0) | H15: =IFERROR(G15/F15,0) | I15: =SUMIF('Trade Log'!E2:E101,E15,'Trade Log'!K2:K101) | J15: =IFERROR(I15/F15,0)
A16: =IF('Trade Log'!A8="","",7) | B16: =IF('Trade Log'!K8="","",'Trade Log'!K8) | C16: =IF(B16="","",C15+B16) | E16: Swing | F16: =COUNTIF('Trade Log'!E2:E101,E16) | G16: =COUNTIFS('Trade Log'!E2:E101,E16,'Trade Log'!K2:K101,">"&0) | H16: =IFERROR(G16/F16,0) | I16: =SUMIF('Trade Log'!E2:E101,E16,'Trade Log'!K2:K101) | J16: =IFERROR(I16/F16,0)
A17: =IF('Trade Log'!A9="","",8) | B17: =IF('Trade Log'!K9="","",'Trade Log'!K9) | C17: =IF(B17="","",C16+B17)
A18: =IF('Trade Log'!A10="","",9) | B18: =IF('Trade Log'!K10="","",'Trade Log'!K10) | C18: =IF(B18="","",C17+B18)
A19: =IF('Trade Log'!A11="","",10) | B19: =IF('Trade Log'!K11="","",'Trade Log'!K11) | C19: =IF(B19="","",C18+B19)
A20: =IF('Trade Log'!A12="","",11) | B20: =IF('Trade Log'!K12="","",'Trade Log'!K12) | C20: =IF(B20="","",C19+B20)
A21: =IF('Trade Log'!A13="","",12) | B21: =IF('Trade Log'!K13="","",'Trade Log'!K13) | C21: =IF(B21="","",C20+B21)
A22: =IF('Trade Log'!A14="","",13) | B22: =IF('Trade Log'!K14="","",'Trade Log'!K14) | C22: =IF(B22="","",C21+B22)
A23: =IF('Trade Log'!A15="","",14) | B23: =IF('Trade Log'!K15="","",'Trade Log'!K15) | C23: =IF(B23="","",C22+B23)
A24: =IF('Trade Log'!A16="","",15) | B24: =IF('Trade Log'!K16="","",'Trade Log'!K16) | C24: =IF(B24="","",C23+B24)
A25: =IF('Trade Log'!A17="","",16) | B25: =IF('Trade Log'!K17="","",'Trade Log'!K17) | C25: =IF(B25="","",C24+B25)
A26: =IF('Trade Log'!A18="","",17) | B26: =IF('Trade Log'!K18="","",'Trade Log'!K18) | C26: =IF(B26="","",C25+B26)
A27: =IF('Trade Log'!A19="","",18) | B27: =IF('Trade Log'!K19="","",'Trade Log'!K19) | C27: =IF(B27="","",C26+B27)
A28: =IF('Trade Log'!A20="","",19) | B28: =IF('Trade Log'!K20="","",'Trade Log'!K20) | C28: =IF(B28="","",C27+B28)
A29: =IF('Trade Log'!A21="","",20) | B29: =IF('Trade Log'!K21="","",'Trade Log'!K21) | C29: =IF(B29="","",C28+B29)
A30: =IF('Trade Log'!A22="","",21) | B30: =IF('Trade Log'!K22="","",'Trade Log'!K22) | C30: =IF(B30="","",C29+B30)
A31: =IF('Trade Log'!A23="","",22) | B31: =IF('Trade Log'!K23="","",'Trade Log'!K23) | C31: =IF(B31="","",C30+B31)
A32: =IF('Trade Log'!A24="","",23) | B32: =IF('Trade Log'!K24="","",'Trade Log'!K24) | C32: =IF(B32="","",C31+B32)
A33: =IF('Trade Log'!A25="","",24) | B33: =IF('Trade Log'!K25="","",'Trade Log'!K25) | C33: =IF(B33="","",C32+B33)
A34: =IF('Trade Log'!A26="","",25) | B34: =IF('Trade Log'!K26="","",'Trade Log'!K26) | C34: =IF(B34="","",C33+B34)
A35: =IF('Trade Log'!A27="","",26) | B35: =IF('Trade Log'!K27="","",'Trade Log'!K27) | C35: =IF(B35="","",C34+B35)
A36: =IF('Trade Log'!A28="","",27) | B36: =IF('Trade Log'!K28="","",'Trade Log'!K28) | C36: =IF(B36="","",C35+B36)
A37: =IF('Trade Log'!A29="","",28) | B37: =IF('Trade Log'!K29="","",'Trade Log'!K29) | C37: =IF(B37="","",C36+B37)
A38: =IF('Trade Log'!A30="","",29) | B38: =IF('Trade Log'!K30="","",'Trade Log'!K30) | C38: =IF(B38="","",C37+B38)
A39: =IF('Trade Log'!A31="","",30) | B39: =IF('Trade Log'!K31="","",'Trade Log'!K31) | C39: =IF(B39="","",C38+B39)
A40: =IF('Trade Log'!A32="","",31) | B40: =IF('Trade Log'!K32="","",'Trade Log'!K32) | C40: =IF(B40="","",C39+B40)
A41: =IF('Trade Log'!A33="","",32) | B41: =IF('Trade Log'!K33="","",'Trade Log'!K33) | C41: =IF(B41="","",C40+B41)
A42: =IF('Trade Log'!A34="","",33) | B42: =IF('Trade Log'!K34="","",'Trade Log'!K34) | C42: =IF(B42="","",C41+B42)
A43: =IF('Trade Log'!A35="","",34) | B43: =IF('Trade Log'!K35="","",'Trade Log'!K35) | C43: =IF(B43="","",C42+B43)
...

Sheet Daily Log
A1: Daily Trading Journal
A2: Track your mindset, preparation, and daily reflections
A4: Date | B4: Pre-Market Notes | C4: Market Bias | D4: # Trades | E4: Daily P&L | F4: What Went Well | G4: What To Improve | H4: Mood (1-5) | I4: Rating (1-5)
A5: 46082 | B5: Watching AAPL breakout level, TSLA earnings reaction | C5: Bullish | D5: 3 | E5: =SUMPRODUCT(('Trade Log'!A2:A101=A5)*('Trade Log'!K2:K101)) | F5: Stuck to plan on AAPL | G5: Cut TSLA loss faster | H5: 4 | I5: 3
A6: 46083 | B6: Gap up in SPY, watching for continuation | C6: Bullish | D6: 2 | E6: =SUMPRODUCT(('Trade Log'!A2:A101=A6)*('Trade Log'!K2:K101)) | F6: Good entry timing on SPY | G6: Overtraded META setup | H6: 3 | I6: 4
E7: =SUMPRODUCT(('Trade Log'!A2:A101=A7)*('Trade Log'!K2:K101))
E8: =SUMPRODUCT(('Trade Log'!A2:A101=A8)*('Trade Log'!K2:K101))
E9: =SUMPRODUCT(('Trade Log'!A2:A101=A9)*('Trade Log'!K2:K101))
E10: =SUMPRODUCT(('Trade Log'!A2:A101=A10)*('Trade Log'!K2:K101))
E11: =SUMPRODUCT(('Trade Log'!A2:A101=A11)*('Trade Log'!K2:K101))
E12: =SUMPRODUCT(('Trade Log'!A2:A101=A12)*('Trade Log'!K2:K101))
E13: =SUMPRODUCT(('Trade Log'!A2:A101=A13)*('Trade Log'!K2:K101))
E14: =SUMPRODUCT(('Trade Log'!A2:A101=A14)*('Trade Log'!K2:K101))
E15: =SUMPRODUCT(('Trade Log'!A2:A101=A15)*('Trade Log'!K2:K101))
E16: =SUMPRODUCT(('Trade Log'!A2:A101=A16)*('Trade Log'!K2:K101))
E17: =SUMPRODUCT(('Trade Log'!A2:A101=A17)*('Trade Log'!K2:K101))
E18: =SUMPRODUCT(('Trade Log'!A2:A101=A18)*('Trade Log'!K2:K101))
E19: =SUMPRODUCT(('Trade Log'!A2:A101=A19)*('Trade Log'!K2:K101))
E20: =SUMPRODUCT(('Trade Log'!A2:A101=A20)*('Trade Log'!K2:K101))
E21: =SUMPRODUCT(('Trade Log'!A2:A101=A21)*('Trade Log'!K2:K101))
E22: =SUMPRODUCT(('Trade Log'!A2:A101=A22)*('Trade Log'!K2:K101))
E23: =SUMPRODUCT(('Trade Log'!A2:A101=A23)*('Trade Log'!K2:K101))
E24: =SUMPRODUCT(('Trade Log'!A2:A101=A24)*('Trade Log'!K2:K101))
E25: =SUMPRODUCT(('Trade Log'!A2:A101=A25)*('Trade Log'!K2:K101))
E26: =SUMPRODUCT(('Trade Log'!A2:A101=A26)*('Trade Log'!K2:K101))
E27: =SUMPRODUCT(('Trade Log'!A2:A101=A27)*('Trade Log'!K2:K101))
E28: =SUMPRODUCT(('Trade Log'!A2:A101=A28)*('Trade Log'!K2:K101))
E29: =SUMPRODUCT(('Trade Log'!A2:A101=A29)*('Trade Log'!K2:K101))
E30: =SUMPRODUCT(('Trade Log'!A2:A101=A30)*('Trade Log'!K2:K101))
E31: =SUMPRODUCT(('Trade Log'!A2:A101=A31)*('Trade Log'!K2:K101))
E32: =SUMPRODUCT(('Trade Log'!A2:A101=A32)*('Trade Log'!K2:K101))
E33: =SUMPRODUCT(('Trade Log'!A2:A101=A33)*('Trade Log'!K2:K101))
E34: =SUMPRODUCT(('Trade Log'!A2:A101=A34)*('Trade Log'!K2:K101))
E35: =SUMPRODUCT(('Trade Log'!A2:A101=A35)*('Trade Log'!K2:K101))
E36: =SUMPRODUCT(('Trade Log'!A2:A101=A36)*('Trade Log'!K2:K101))
E37: =SUMPRODUCT(('Trade Log'!A2:A101=A37)*('Trade Log'!K2:K101))
E38: =SUMPRODUCT(('Trade Log'!A2:A101=A38)*('Trade Log'!K2:K101))
E39: =SUMPRODUCT(('Trade Log'!A2:A101=A39)*('Trade Log'!K2:K101))
E40: =SUMPRODUCT(('Trade Log'!A2:A101=A40)*('Trade Log'!K2:K101))
E41: =SUMPRODUCT(('Trade Log'!A2:A101=A41)*('Trade Log'!K2:K101))
...

Sheet How To Use
B2: Free Trading Journal Template
B3: by TradingJournal.com
B5: GETTING STARTED
B6: 1. Go to the Trade Log tab and start entering your trades.
B7: 2. The Dashboard tab auto-calculates your stats — no manual work needed.
B8: 3. Use the Daily Log tab to track your mindset and daily reflections.
B10: TRADE LOG TIPS
B11: - Side: Select Long or Short from the dropdown.
B12: - Gross P&L and Net P&L are auto-calculated from your entry/exit prices.
B13: - Add your commission/fees in the Fees column.
B14: - Use the Strategy column consistently (e.g., always 'Breakout', not 'breakout').
B15: - The Notes column is your best friend — write WHY you took the trade.
... B30: trading journal software at tradingjournal.com
